<mujoco model="three_fingertip_cube">
    <compiler angle="radian"/>
    <size njmax="500" nconmax="100"/>
    <asset>
        <mesh name="object" file="../pc/foam_brick.stl"/>
        <texture type="2d" name="groundplane" builtin="checker" mark="edge" rgb1="0.2 0.3 0.4"
        rgb2="0.1 0.2 0.3" markrgb="0.8 0.8 0.8" width="300" height="300"/>
        <material name="groundplane" texture="groundplane" texuniform="true" texrepeat="5 5"
        reflectance="0.2"/>
    </asset>

    <worldbody>
        <light pos="0 0 1"/>
        <light pos="0.3 0 1.5" dir="0 0 -1" directional="true"/>
        <light diffuse="0.9 0.9 0.9" pos="2 2 2" dir="0 0 -1" directional="true"/>


        <!-- ============================= virtual obj ========================================= -->
        <!-- pos and quat attributes of virtual obj must be put in 'geom' -->
        <body name="goal" >
            <geom name="goal" type="mesh" mesh="object" conaffinity="0" contype="0"
                pos="0.0 0.0 0.0" quat="1 0 0 0"
                rgba="0 0.5 0 0.2"/>
            <site type="box" size="0.05 0.003 0.003" rgba="1 0 0 1" pos="0.05 0 0"/>
            <site type="box" size="0.003 0.05 0.003" rgba="0 1 0 1" pos="0 0.05 0"/>
            <site type="box" size="0.003 0.003 0.05" rgba="0 0 1 1" pos="0 0 0.05"/>
        </body>

        <!-- ============================= real obj ========================================= -->
        <body name="cube" >
            <freejoint name="cube_table"/>
            <geom name="cube" type="mesh" mesh="object"
                pos="0.0 0.0 0.0" quat="1 0 0 0"
                mass="0.01"
                condim="6"
                friction="0.5" rgba="0 0 0.5 1.0"/>
            <site type="box" size="0.05 0.003 0.003" rgba="1 0 0 1" pos="0.05 0 0"/>
            <site type="box" size="0.003 0.05 0.003" rgba="0 1 0 1" pos="0 0.05 0"/>
            <site type="box" size="0.003 0.003 0.05" rgba="0 0 1 1" pos="0 0 0.05"/>
        </body>

        <geom name="table" rgba="0.8 0.8 0.8 1.0" friction="0.5"
                size="0 0 0.05" type="plane" material="groundplane" 
                condim="6"
              />

        <body name="fingertip0" pos="0.0 0.0 0.0" quat="1 0 0 0">
            <joint name="fingertip0_x" type="slide" axis="1 0 0"/>
            <joint name="fingertip0_y" type="slide" axis="0 1 0"/>
            <joint name="fingertip0_z" type="slide" axis="0 0 1"/>
            <geom name="fingertip0" 
                condim="6"
                pos="0.0 0.0 0.0" quat="1 0 0 0"
                size="0.01" type="sphere" friction="0.5" rgba="0.5 0 0 1"/>
        </body>

        <body name="fingertip1" pos="0.0 0.0 0.0" quat="1 0 0 0">
            <joint name="fingertip1_x" type="slide" axis="1 0 0"/>
            <joint name="fingertip1_y" type="slide" axis="0 1 0"/>
            <joint name="fingertip1_z" type="slide" axis="0 0 1"/>
            <geom name="fingertip1" 
                condim="6"
                pos="0.0 0.0 0.0" quat="1 0 0 0"
                size="0.01" type="sphere" friction="0.5" rgba="0 0.5 0 1"/>
        </body>

        <body name="fingertip2" pos="0.0 0.0 0.0" quat="1 0 0 0">
            <joint name="fingertip2_x" type="slide" axis="1 0 0"/>
            <joint name="fingertip2_y" type="slide" axis="0 1 0"/>
            <joint name="fingertip2_z" type="slide" axis="0 0 1"/>
            <geom name="fingertip2" 
                condim="6"
                pos="0.0 0.0 0.0" quat="1 0 0 0"
                size="0.01" type="sphere" friction="0.5" rgba="0 0 0.5 1"/>
        </body>

    </worldbody>

    <actuator>
        <motor name="fingertip0_refx" joint="fingertip0_x" ctrlrange="-1.5 1.5" ctrllimited="false"/>
        <motor name="fingertip0_refy" joint="fingertip0_y" ctrlrange="-1.5 1.5" ctrllimited="false"/>
        <motor name="fingertip0_refz" joint="fingertip0_z" ctrlrange="-1.5 1.5" ctrllimited="false"/>
        <motor name="fingertip1_refx" joint="fingertip1_x" ctrlrange="-1.5 1.5" ctrllimited="false"/>
        <motor name="fingertip1_refy" joint="fingertip1_y" ctrlrange="-1.5 1.5" ctrllimited="false"/>
        <motor name="fingertip1_refz" joint="fingertip1_z" ctrlrange="-1.5 1.5" ctrllimited="false"/>
        <motor name="fingertip2_refx" joint="fingertip2_x" ctrlrange="-1.5 1.5" ctrllimited="false"/>
        <motor name="fingertip2_refy" joint="fingertip2_y" ctrlrange="-1.5 1.5" ctrllimited="false"/>
        <motor name="fingertip2_refz" joint="fingertip2_z" ctrlrange="-1.5 1.5" ctrllimited="false"/>
    </actuator>
</mujoco>
